Workbook

Sheet INFO 
A1: LEER ANTES COMO HACER TU COMPRA:
A2: RECOMENDAMOS VER DESDE UNA COMPUTADORA
A3: 1 Guardá el archivo Antes de empezar, guardá esta lista en tu computadora con el nombre de tu pet shop o veterinaria y la fecha. Así podremos identificar tu pedido cuando nos lo envíes.
A4: 2 Conocé la estructura del archivo En la segunda hoja llamada PRESUPUESTO vas a ver el resumen total de tu pedido (¡no tenés que completar nada ahí!). Luego, en las siguientes hojas encontrarás nuestros productos separados por ancho de collar y pretal.
A5: 3 Completá tu pedido En cada hoja en el recuadro VIOLETA escribí la cantidad de unidades que querés de cada modelo. Podés detallar los colores que preferís. En SUBTOTAL se calculará automáticamente cuánto suma cada producto que elijas.
A6: 4 Volvemos a la hoja PRESUPUESTO Al terminar de completar todas las hojas, en la hoja inicial PRESUPUESTO vas a ver el resumen por anchos. COMPRA TOTAL: suma total de todos los productos que elegiste.
A7: 5 Datos de contacto Recordá completar tus datos en el recuadro de abajo del presupuesto, arriba nos ocupamos nosotros.
A8: 6 Envianos tu pedido Cuando termines, enviá esta planilla a nuestro WhatsApp: 1161214064 (Yael y Matías)
A9: 7 Confirmacion del pedido Nos vamos a contactar con vos para confirmar que lo recibimos enviandote nuestros datos para el envio del 50% del total del pedido, una vez enviado eso comenzamos a realizar el mismo.
A10: 8 Dudas? Escribinos al WhatsApp: 1161214064 (Yael y Matías) — ¡Estamos para ayudarte!

Sheet Presupuesto
B1: DOCUMENTO NO VALIDO COMO FACTURA | C1: PRESUPUESTO
B3: instagram: @wawpetaccesorios | C3: 0000- XXXX
B4: Contacto: Cel: 116121-4064 | C4: Horario
B5: Tienda:
A7: FECHA | B7: Direccion: | C7: PEDIDO POR
B8: Tel:
A9: Codigo | B9: Producto | C9: Unidades | D9: Precio Total
A10: 400/500 | B10: COLLARES ELASTIZADOS PARA GATOS | C10: =+'Gatos Ancho 10mm'!D45 -> 0 | D10: =+'Gatos Ancho 10mm'!E45:E45 -> 0
A12: 1000 | B12: COLLARES ANCHO 10 mm VARIOS MODELOS Y TALLES | C12: =+'Perros Ancho 10mm'!D48 -> 0 | D12: =+'Perros Ancho 10mm'!E48 -> 0
A13: 1500 | B13: COLLARES ANCHO 15 mm VARIOS MODELOS Y TALLES | C13: =+'Ancho 15mm'!D61 -> 0 | D13: =+'Ancho 15mm'!E61 -> 0
A14: 2000 | B14: COLLARES ANCHO 20 mm VARIOS MODELOS Y TALLES | C14: =+'Ancho 20mm'!D64 -> 0 | D14: =+'Ancho 20mm'!E64 -> 0
A15: 2500 | B15: COLLARES ANCHO 25 mm VARIOS MODELOS Y TALLES | C15: =+'Ancho 25mm'!D33 -> 0 | D15: =+'Ancho 25mm'!E33 -> 0
A16: 3000 | B16: COLLARES ANCHO 30 mm VARIOS MODELOS Y TALLES | C16: =+'Ancho 30mm'!D70 -> 0 | D16: =+'Ancho 30mm'!E70 -> 0
A17: 4000 | B17: COLLARES ANCHO 40 mm VARIOS MODELOS Y TALLES | C17: =+'Ancho 40mm'!D16 -> 0 | D17: =+'Ancho 40mm'!E16 -> 0
A18: 5000 | B18: COLLARES ANCHO 50 mm VARIOS MODELOS Y TALLES | C18: =+'Ancho 50mm'!D18 -> 0 | D18: =+'Ancho 50mm'!E18 -> 0
A20: 2090 | B20: PRETALES H ANCHO 10 mm VARIOS MODELOS Y TALLES | C20: =+'Perros Ancho 10mm'!D53 -> 0 | D20: =+'Perros Ancho 10mm'!E58 -> 0
A21: 2090 | B21: PRETALES H ANCHO 15 mm VARIOS MODELOS Y TALLES | C21: =+'Ancho 15mm'!D66 -> 0 | D21: =+'Ancho 15mm'!E74 -> 0
A22: 2090 | B22: PRETALES H ANCHO 20 mm VARIOS MODELOS Y TALLES | C22: =+'Ancho 20mm'!D77 -> 0 | D22: =+'Ancho 20mm'!E77 -> 0
A23: 2590 | B23: PRETALES H ANCHO 25 mm VARIOS MODELOS Y TALLES | C23: =+'Ancho 25mm'!D46 -> 0 | D23: =+'Ancho 25mm'!E46 -> 0
A24: 3090 | B24: PRETALES H ANCHO 30 mm VARIOS MODELOS Y TALLES | C24: =+'Ancho 30mm'!D83 -> 0 | D24: =+'Ancho 30mm'!E83 -> 0
A25: 4090 | B25: PRETALES H ANCHO 40 mm VARIOS MODELOS Y TALLES | C25: =+'Ancho 40mm'!D23 -> 0 | D25: =+'Ancho 40mm'!E23 -> 0
A26: 5090 | B26: PRETALES H ANCHO 50 mm VARIOS MODELOS Y TALLES | C26: =+'Ancho 50mm'!D25 -> 0 | D26: =+'Ancho 50mm'!E25 -> 0
A28: NOTAS: | C28: COMPRA TOTAL: | D28: =SUM(D10:D27) -> 0
A30: DATOS PARA COMPLETAR:
A31: Veterinaria:
A32: Telefono:
A33: Direccion:
A34: Horario de atencion:
A35: Pedido por:
A36: Retira en sucursal o envio a domicilio: (completar si queres envio)
A37: Destino:
A38: CP:
A39: DNI: (necesario si queres envio a domicilio por transporte)
A40: E-mail:

Sheet Gatos Ancho 10mm
A1: COLLAR ANCHO 10 mm
A2: Cod.-Talle | B2: COLLARES ELASTIZADOS PARA GATOS | C2: Precio Unit | D2: Cantidad | E2: Precio Total | F2: Colores de tu preferencia
F3: Rojo-turqueza-plateado-fucsia-rosa
A4: 401/25 | B4: COLLAR SEMI- ELASTIZADO CADENA COLOR NUEVO!! | C4: =+'[1]C.GATOS'!$U$12 -> 3200 | E4: =+D4*C4 -> 0
F5: Rojo-francia-negro-fucsia-violeta
A6: 402/25 | B6: COLLAR SEMI- ELASTIZADO GAMUZADO STRASS | C6: =+'[2]C.GATOS'!$U$14 -> 4600 | E6: =+D6*C6 -> 0
F7: Rojo-francia-negro-fucsia-violeta
A8: 403/25 | B8: COLLAR SEMI- ELASTIZADO GAMUZADO CUADRADOS STRASS | C8: =+'[2]C.GATOS'!$U$14 -> 4600 | E8: =+D8*C8 -> 0
F9: Francia-rojo-negro-fucsia
A10: 404/25 | B10: COLLAR SEMI- ELASTIZADO GAMUZADO STRASS MULTICOLOR | C10: =+'[2]C.GATOS'!$Z$12 -> 4600 | E10: =+D10*C10 -> 0
F11: Rojo-francia-negro-rosa-violeta
A12: 405/25 | B12: COLLAR SEMI- ELASTIZADO PERLAS COLOR | C12: =+'[2]C.GATOS'!$Z$11 -> 4200 | E12: =+D12*C12 -> 0
F13: Francia-rojo-celeste-fucsia-violeta-gris-negro c/naranja
A14: 406/25 | B14: COLLAR SEMI- ELASTIZADO GAMUZADO MOSTACILLA MULTICOLOR | C14: =+'[2]C.GATOS'!$Z$11 -> 4200 | E14: =+D14*C14 -> 0
F15: Francia-negro-rojo-turq-verde-amarillo-rosa-fucsia-violeta-fluo amarillo-fluo fucsia-fluo naranja-fluo verde
A16: 501/25 | B16: COLLAR ELASTIZADO AJUSTABLE LISO | C16: =+'[2]C.GATOS'!$U$53 -> 2850 | E16: =+D16*C16 -> 0
F17: Rojo-negro-rosa-blanco-lila-francia-print-oro-plata-fucsia-fluo naranja-fucsia y verde
A18: 502/25 | B18: COLLAR ELASTIZADO ARRUGADO | C18: =+'[2]C.GATOS'!$Z$14 -> 3150 | E18: =+D18*C18 -> 0
F19: Rojo-negro-rosa-blanco-lila-francia-print-oro-plata-fucsia-fluo naranja-fucsia y verde PEDIR FOTO MOÑOS
A20: 503/25 | B20: COLLAR ELASTIZADO ARRUGADO C/ MOÑO TELA | C20: =+'[2]C.GATOS'!$Z$13 -> 4900 | E20: =+D20*C20 -> 0
F21: Negro
A22: 504/25 | B22: COLLAR ELASTIZADO AJUSTABLE CON STRASS | C22: =+'[2]C.GATOS'!$Z$6 -> 3300 | E22: =+D22*C22 -> 0
F23: Negro con lunares-negro con patitas y corazones
A24: 505/25 | B24: COLLAR ELASTIZADO AJUSTABLE ESTAMPADO | C24: =+'[2]C.GATOS'!$Z$7 -> 3100 | E24: =+D24*C24 -> 0
F25: Violeta-negro-rojo-coral-blanco-lila
A26: 506/25 | B26: COLLAR ELASTIZADO AJUSTABLE PRINT CEBRA | C26: =+'[2]C.GATOS'!$Z$7 -> 3100 | E26: =+D26*C26 -> 0
F27: Fucsia-verde-gris-celeste
A28: 507/25 | B28: COLLAR ELASTIZADO AJUSTABLE CAMUFLADO | C28: =+'[2]C.GATOS'!$Z$7 -> 3100 | E28: =+D28*C28 -> 0
F29: Violeta-negro-rojo-coral-blanco-beige
A30: 508/25 | B30: COLLAR ELASTIZADO AJUSTABLE ESTRELLAS | C30: =+'[2]C.GATOS'!$Z$7 -> 3100 | E30: =+D30*C30 -> 0
F31: Beige-celeste-rojo-turqueza-blanco
A32: 509/25 | B32: COLLAR ELASTIZADO AJUSTABLE PRINT LEOPARDO | C32: =+'[2]C.GATOS'!$Z$7 -> 3100 | E32: =+D32*C32 -> 0
F33: Verde y rojo-azul y rojo-blanco y negro-negro y gris-azul,blanco y rosa-negro,blanco y rojo
A34: 510/25 | B34: COLLAR ELASTIZADO AJUSTABLE RAYADO | C34: =+'[2]C.GATOS'!$Z$6 -> 3300 | E34: =+D34*C34 -> 0
F35: Francia-oro-plata-fucsia-beige-negro
A36: 511/25 | B36: COLLAR ELASTIZADO AJUSTABLE BRILLOSO | C36: =+'[2]C.GATOS'!$Z$6 -> 3300 | E36: =+D36*C36 -> 0
F37: Francia-negro-rojo-naranja-amarillo-rosa-fluo verde-violeta
A38: 512/25 | B38: COLLAR ELASTIZADO AJUSTABLE CON MOÑO | C38: =+'[2]C.GATOS'!$Z$8 -> 3450 | E38: =+D38*C38 -> 0
F39: Rojo-negro-fucsia-rosa-violeta-fluo fucsia-amarillo
A40: 513/25 | B40: COLLAR ELASTIZADO AJUSTABLE C/ FLOR | C40: =+'[2]C.GATOS'!$Z$8 -> 3450 | E40: =+D40*C40 -> 0
...

Sheet Perros Ancho 10mm
A1: COLLAR ANCHO 10 mm
B2: Productos para PERROS | C2: Precio Unit | D2: Cantidad | E2: Precio Total | F2: Colores de tu preferencia
A3: Cod.-Talle | B3: COLLAR LISO 10mm | F3: Charol:negro-rojo-fucsia-francia / Simil Cuero Cosido:negro-plata-rosa-oro-turqueza-rojo-violeta-francia
A4: 1010/25 | B4: COLLAR LISO 10mm | C4: =+'[2]Collares 10mm'!$U$4-100 -> 4400 | E4: =+D4*C4 -> 0
A5: 1010/30 | B5: COLLAR LISO 10mm | C5: =+'[2]Collares 10mm'!$U$4-50 -> 4450 | E5: =+D5*C5 -> 0
A6: 1010/35 | B6: COLLAR LISO 10mm | C6: =+'[2]Collares 10mm'!$U$4 -> 4500 | E6: =+D6*C6 -> 0
A7: Cod.-Talle | B7: COLLAR TEXANO 10mm | F7: Colores en simil cuero cosido: negro-plata-oro-rojo -rosa-turqueza-francia
A8: 1020/25 | B8: COLLAR TEXANO 10mm | C8: =+'[2]Collares 10mm'!$U$9 -> 5800 | E8: =+D8*C8 -> 0
A9: 1020/30 | B9: COLLAR TEXANO 10mm | C9: =+'[2]Collares 10mm'!$U$9+50 -> 5850 | E9: =+D9*C9 -> 0
A10: 1020/35 | B10: COLLAR TEXANO 10mm | C10: =+'[2]Collares 10mm'!$U$9+100 -> 5900 | E10: =+D10*C10 -> 0
A11: Cod.-Talle | B11: COLLAR PUAS 10mm | F11: Simil cuero cosido: negro-plata-oro-rosa-rojo-fluo-fucsia-francia / Print: leopardo-gris
A12: 1030/25 | B12: COLLAR PUAS 10mm | C12: =+'[2]Collares 10mm'!$U$13 -> 6800 | E12: =+D12*C12 -> 0
A13: 1030/30 | B13: COLLAR PUAS 10mm | C13: =+'[2]Collares 10mm'!$U$13+50 -> 6850 | E13: =+D13*C13 -> 0
A14: 1030/35 | B14: COLLAR PUAS 10mm | C14: =+'[2]Collares 10mm'!$U$13+100 -> 6900 | E14: =+D14*C14 -> 0
A15: Cod.-Talle | B15: COLLAR CON LETRAS STRASS 10mm | F15: Simil cuero cosido: negro-plata-oro-rosa-rojo-fluo-fucsia-francia / Charol: negro-rojo-fucsia-francia
A16: 1051/25 | B16: COLLAR CON LETRAS STRASS 10mm | C16: =+'[2]Collares 10mm'!$U$11 -> 8200 | E16: =+D16*C16 -> 0
A17: 1051/30 | B17: COLLAR CON LETRAS STRASS 10mm | C17: =+'[2]Collares 10mm'!$U$11+50 -> 8250 | E17: =+D17*C17 -> 0
A18: 1051/35 | B18: COLLAR CON LETRAS STRASS 10mm | C18: =+'[2]Collares 10mm'!$U$11+100 -> 8300 | E18: =+D18*C18 -> 0
A19: Cod.-Talle | B19: COLLAR GARGANTILLA STRASS Dije strass: dog-corona-corazon-cruz | F19: Simil cuero cosido: negro-plata-oro-rosa-rojo-fluo-fucsia-francia / Print: leopardo-gris
A20: 1052/25 | B20: COLLAR GARGANTILLA STRASS | C20: =+'[2]Collares 10mm'!$U$22 -> 5800 | E20: =+D20*C20 -> 0
A21: 1052/30 | B21: COLLAR GARGANTILLA STRASS | C21: =+'[2]Collares 10mm'!$U$22+50 -> 5850 | E21: =+D21*C21 -> 0
A22: 1052/35 | B22: COLLAR GARGANTILLA STRASS | C22: =+'[2]Collares 10mm'!$U$22+100 -> 5900 | E22: =+D22*C22 -> 0
A23: Cod.-Talle | B23: COLLAR GAMUZA PERLAS COLORES | F23: Gamuza: rojo-negro-francia-violeta-fucsia
A24: 1053/25 | B24: COLLAR GAMUZA PERLAS COLORES | C24: =+'[2]Collares 10mm'!$U$48 -> 5000 | E24: =+D24*C24 -> 0
A25: 1053/30 | B25: COLLAR GAMUZA PERLAS COLORES | C25: =+'[2]Collares 10mm'!$U$48+50 -> 5050 | E25: =+D25*C25 -> 0
A26: 1053/35 | B26: COLLAR GAMUZA PERLAS COLORES | C26: =+'[2]Collares 10mm'!$U$48+100 -> 5100 | E26: =+D26*C26 -> 0
A27: Cod.-Talle | B27: COLLAR CORAZON | F27: Charol: negro-rojo-fucsia-francia / Simil Cuero Cosido: negro-plata-rosa-oro-turqueza-rojo-violeta -francia
A28: 1054/25 | B28: COLLAR CORAZON | C28: =+'[2]Collares 10mm'!$U$26 -> 5500 | E28: =+D28*C28 -> 0
A29: 1054/30 | B29: COLLAR CORAZON | C29: =+'[2]Collares 10mm'!$U$26+50 -> 5550 | E29: =+D29*C29 -> 0
A30: 1054/35 | B30: COLLAR CORAZON | C30: =+'[2]Collares 10mm'!$U$26+100 -> 5600 | E30: =+D30*C30 -> 0
A31: Cod.-Talle | B31: COLLAR SIMBOLO DE LA PAZ | F31: Charol: negro-rojo-fucsia-francia / Simil Cuero Cosido: negro-plata-rosa-oro-turqueza-rojo-violeta -francia
A32: 1055/25 | B32: COLLAR SIMBOLO DE LA PAZ | C32: =+'[2]Collares 10mm'!$U$28 -> 5500 | E32: =+D32*C32 -> 0
A33: 1055/30 | B33: COLLAR SIMBOLO DE LA PAZ | C33: =+'[2]Collares 10mm'!$U$28+50 -> 5550 | E33: =+D33*C33 -> 0
A34: 1055/35 | B34: COLLAR SIMBOLO DE LA PAZ | C34: =+'[2]Collares 10mm'!$U$28+100 -> 5600 | E34: =+D34*C34 -> 0
A35: Cod./Talle | B35: COLLAR CON MOÑO 10mm | F35: Colores moño brillosos: oro-rosa-plata-negro-gris-rojo / Colores moño estampado cuadrille: fucsia-negro
A36: 1056/25 | B36: COLLAR CON MOÑO 10mm | C36: =+'[2]Collares 10mm'!$U$3 -> 5500 | E36: =+D36*C36 -> 0
A37: 1056/30 | B37: COLLAR CON MOÑO 10mm | C37: =+'[2]Collares 10mm'!$U$3+50 -> 5550 | E37: =+D37*C37 -> 0
A38: 1056/35 | B38: COLLAR CON MOÑO 10mm | C38: =+'[2]Collares 10mm'!$U$3+100 -> 5600 | E38: =+D38*C38 -> 0
A39: Cod.-Talle | B39: COLLAR MOÑO TELA C/STRASS | F39: Colores Moño: rosa-fucsia
A40: 1057/25 | B40: COLLAR MOÑO TELA C/STRASS | C40: =+'[2]Collares 10mm'!$U$17 -> 5550 | E40: =+D40*C40 -> 0
...

Sheet Ancho 15mm
A1: COLLAR ANCHO 15 mm
B2: Productos para PERROS | C2: Precio Unit | D2: Cantidad | E2: Precio Total | F2: Colores de tu preferencia
A3: Cod.-Talle | B3: COLLAR NYLON LISO C/PASADOR CUERINA COLOR Y DIJE 15mm | F3: Colores: rojo-negro-francia-violeta-fucsia-rosa-turqueza-naranja
A4: 1510/25 | B4: COLLAR NYLON LISO C/PASADOR CUERINA COLOR Y DIJE 15mm | C4: =+'[2]C.PO.15 mm'!$S$28 -> 4550 | E4: =+D4*C4 -> 0
A5: 1510/30 | B5: COLLAR NYLON LISO C/PASADOR CUERINA COLOR Y DIJE 15mm | C5: =+'[2]C.PO.15 mm'!$S$29 -> 4600 | E5: =+D5*C5 -> 0
A6: 1510/35 | B6: COLLAR NYLON LISO C/PASADOR CUERINA COLOR Y DIJE 15mm | C6: =+'[2]C.PO.15 mm'!$S$30 -> 4650 | E6: =+D6*C6 -> 0
A7: 1510/40 | B7: COLLAR NYLON LISO C/PASADOR CUERINA COLOR Y DIJE 15mm | C7: =+'[2]C.PO.15 mm'!$S$31 -> 4700 | E7: =+D7*C7 -> 0
A8: 1510/CO | B8: CORREA NYLON LISO 15mm (1,20 m) | C8: =+'[2]C.PO.15 mm'!$S$3 -> 3970 | E8: =+D8*C8 -> 0
A9: Cod.-Talle | B9: COLLAR C/ PUAS 15mm | F9: Simil cuero cosido: negro-oro-rojo-plata-fluo-fucsia-rosa-francia Charol: negro-rojo-violeta-azul francia-fucsia
A10: 1530/30 | B10: COLLAR C/ PUAS 15mm | C10: =+'[2]Collares15 mm'!$U$10 -> 7150 | E10: =+D10*C10 -> 0
A11: 1530/35 | B11: COLLAR C/ PUAS 15mm | C11: =+'[2]Collares15 mm'!$U$10+50 -> 7200 | E11: =+D11*C11 -> 0
A12: 1530/40 | B12: COLLAR C/ PUAS 15mm | C12: =+'[2]Collares15 mm'!$U$10+100 -> 7250 | E12: =+D12*C12 -> 0
A13: Cod.-Talle | B13: COLLAR TACHAS STRASS 15mm | F13: Simil cuero cosido: negro-oro-rojo-plata-fluo-fucsia-rosa-francia Charol: negro-rojo-violeta-azul francia-fucsia
A14: 1531/30 | B14: COLLAR TACHAS STRASS 15mm | C14: =+'[2]Collares15 mm'!$U$9 -> 5950 | E14: =+D14*C14 -> 0
A15: 1531/35 | B15: COLLAR TACHAS STRASS 15mm | C15: =+'[2]Collares15 mm'!$U$9+50 -> 6000 | E15: =+D15*C15 -> 0
A16: 1531/40 | B16: COLLAR TACHAS STRASS 15mm | C16: =+'[2]Collares15 mm'!$U$9+100 -> 6050 | E16: =+D16*C16 -> 0
A17: 1531/45 | B17: COLLAR TACHAS STRASS 15mm | C17: =+'[2]Collares15 mm'!$U$9+150 -> 6100 | E17: =+D17*C17 -> 0
A18: Cod.-Talle | B18: COLLAR PUAS Y TACHAS STRASS 15mm | F18: Simil cuero cosido: negro-oro-rojo-plata-fluo-fucsia-rosa-francia Charol: negro-rojo-violeta-azul francia-fucsia
A19: 1532/25 | B19: COLLAR PUAS Y TACHAS STRASS 15mm | C19: =+'[2]Collares15 mm'!$U$12 -> 6550 | E19: =+D19*C19 -> 0
A20: 1532/30 | B20: COLLAR PUAS Y TACHAS STRASS 15mm | C20: =+'[2]Collares15 mm'!$U$12+50 -> 6600 | E20: =+D20*C20 -> 0
A21: 1532/35 | B21: COLLAR PUAS Y TACHAS STRASS 15mm | C21: =+'[2]Collares15 mm'!$U$12+100 -> 6650 | E21: =+D21*C21 -> 0
A22: 1532/40 | B22: COLLAR PUAS Y TACHAS STRASS 15mm | C22: =+'[2]Collares15 mm'!$U$12+150 -> 6700 | E22: =+D22*C22 -> 0
A23: 1532/45 | B23: COLLAR PUAS Y TACHAS STRASS 15mm | C23: =+'[2]Collares15 mm'!$U$12+200 -> 6750 | E23: =+D23*C23 -> 0
A24: Cod.-Talle | B24: COLLAR NYLON FASHION 15mm | F24: Simil cuero cosido: negro-oro-rojo-plata-fluo-fucsia-rosa-francia Charol: negro-rojo-violeta-azul francia-fucsia
A25: 1540/25 | B25: COLLAR NYLON FASHION 15mm | C25: =+'[2]C.PO.15 mm'!$S$34 -> 5200 | E25: =+D25*C25 -> 0
A26: 1540/30 | B26: COLLAR NYLON FASHION 15mm | C26: =+'[2]C.PO.15 mm'!$S$35 -> 5250 | E26: =+D26*C26 -> 0
A27: 1540/35 | B27: COLLAR NYLON FASHION 15mm | C27: =+'[2]C.PO.15 mm'!$S$36 -> 5300 | E27: =+D27*C27 -> 0
A28: 1540/40 | B28: COLLAR NYLON FASHION 15mm | C28: =+'[2]C.PO.15 mm'!$S$37 -> 5350 | E28: =+D28*C28 -> 0
A29: 1540/45 | B29: COLLAR NYLON FASHION 15mm | C29: =+'[2]C.PO.15 mm'!$S$37+50 -> 5400 | E29: =+D29*C29 -> 0
A30: 1540/CO | B30: CORREA NYLON FASHION 15mm (1,20 m) | C30: =+'[2]C.PO.15 mm'!$S$6 -> 5800 | E30: =+D30*C30 -> 0
A31: Cod.-Talle | B31: COLLAR NYLON MOSTACILLA MULTICOLOR Y DIJE 15mm | F31: Colores: turqueza-naranja-violeta-rojo-fucsia-francia-negro-rosa
A32: 1550/25 | B32: COLLAR NYLON MOSTACILLA MULTICOLOR Y DIJE 15mm | C32: =+'[2]C.PO.15 mm'!$S$40 -> 5800 | E32: =+D32*C32 -> 0
A33: 1550/30 | B33: COLLAR NYLON MOSTACILLA MULTICOLOR Y DIJE 15mm | C33: =+'[2]C.PO.15 mm'!$S$41 -> 5850 | E33: =+D33*C33 -> 0
A34: 1550/35 | B34: COLLAR NYLON MOSTACILLA MULTICOLOR Y DIJE 15mm | C34: =+'[2]C.PO.15 mm'!$S$42 -> 5900 | E34: =+D34*C34 -> 0
A35: 1550/40 | B35: COLLAR NYLON MOSTACILLA MULTICOLOR Y DIJE 15mm | C35: =+'[2]C.PO.15 mm'!$S$43 -> 5950 | E35: =+D35*C35 -> 0
A36: 1550/45 | B36: COLLAR NYLON MOSTACILLA MULTICOLOR Y DIJE 15mm | C36: =+'[2]C.PO.15 mm'!$S$44 -> 6000 | E36: =+D36*C36 -> 0
A37: 1550/CO | B37: CORREA NYLON MOSTACILLA MULTICOLOR C/MOSQUETON REFORZADO 15mm (1,20 m) | C37: =+'[2]C.PO.15 mm'!$S$8 -> 5200 | E37: =+D37*C37 -> 0
A38: Cod.-Talle | B38: COLLAR CON MOÑO BRILLOSO 15mm | F38: Moño estampado cuadrille: fucsia-negro Moños brillosos: oro-rosa-plata-negro-gris-rojo
A39: 1551/30 | B39: COLLAR CON MOÑO BRILLOSO 15mm | C39: =+'[2]Collares15 mm'!$U$22 -> 5950 | E39: =+D39*C39 -> 0
A40: 1551/35 | B40: COLLAR CON MOÑO BRILLOSO 15mm | C40: =+'[2]Collares15 mm'!$U$22+50 -> 6000 | E40: =+D40*C40 -> 0
...

Sheet Ancho 20mm
A1: COLLAR ANCHO 20 mm
B2: Productos para PERROS | C2: Precio Unit | D2: Cantidad | E2: Precio Total | F2: Colores de tu preferencia
A3: Cod.-Talle | B3: COLLAR NYLON LISO C/PASADOR CUERINA COLOR Y DIJE 20mm | F3: Charol: fucsia-negro-rojo-blanco-francia Simil cuero cosido: oro-negro-rosa-fluo-fucsia
A4: 2010/30 | B4: COLLAR NYLON LISO C/PASADOR CUERINA COLOR Y DIJE 20mm | C4: =+'[2]C.PO. 20 mm'!$R$24 -> 4500 | E4: =+D4*C4 -> 0
A5: 2010/35 | B5: COLLAR NYLON LISO C/PASADOR CUERINA COLOR Y DIJE 20mm | C5: =+'[2]C.PO. 20 mm'!$R$25 -> 4550 | E5: =+D5*C5 -> 0
A6: 2010/40 | B6: COLLAR NYLON LISO C/PASADOR CUERINA COLOR Y DIJE 20mm | C6: =+'[2]C.PO. 20 mm'!$R$26 -> 4600 | E6: =+D6*C6 -> 0
A7: 2010/45 | B7: COLLAR NYLON LISO C/PASADOR CUERINA COLOR Y DIJE 20mm | C7: =+'[2]C.PO. 20 mm'!$R$27 -> 4650 | E7: =+D7*C7 -> 0
A8: 2010/CO | B8: CORREA NYLON LISO 20mm (1,20 m) | C8: =+'[4]C.PO. 20 mm'!$R$3 -> 4350 | E8: =+D8*C8 -> 0
A9: Cod.-Talle | B9: COLLAR POLIPROPILENO TEXANO 20 mm | F9: Colores: rojo-negro-rosa-francia
A10: 2020/30 | B10: COLLAR POLIPROPILENO TEXANO 20mm | C10: =+'[2]C.PO. 20 mm'!$R$51 -> 5550 | E10: =+D10*C10 -> 0
A11: 2020/35 | B11: COLLAR POLIPROPILENO TEXANO 20mm | C11: =+'[2]C.PO. 20 mm'!$R$52 -> 5600 | E11: =+D11*C11 -> 0
A12: 2020/40 | B12: COLLAR POLIPROPILENO TEXANO 20mm | C12: =+'[2]C.PO. 20 mm'!$R$53 -> 5650 | E12: =+D12*C12 -> 0
A13: 2020/45 | B13: COLLAR POLIPROPILENO TEXANO 20mm | C13: =+'[2]C.PO. 20 mm'!$R$54 -> 5700 | E13: =+D13*C13 -> 0
A14: Cod.-Talle | B14: COLLAR TEXANO 20mm | F14: Colores: negro-rojo-plata-oro
A15: 2021/30 | B15: COLLAR TEXANO 20mm | C15: =+'[2]C.S.C.20 mm'!$U$10 -> 7100 | E15: =+D15*C15 -> 0
A16: 2021/35 | B16: COLLAR TEXANO 20mm | C16: =+'[2]C.S.C.20 mm'!$U$10+50 -> 7150 | E16: =+D16*C16 -> 0
A17: 2021/40 | B17: COLLAR TEXANO 20mm | C17: =+'[2]C.S.C.20 mm'!$U$10+100 -> 7200 | E17: =+D17*C17 -> 0
A18: 2021/45 | B18: COLLAR TEXANO 20mm | C18: =+'[2]C.S.C.20 mm'!$U$10 -> 7100 | E18: =+D18*C18 -> 0
A19: Cod.-Talle | B19: COLLAR PUAS Y TACHAS STRASS 20mm | F19: Charol: fucsia-negro-rojo-blanco-francia Simil cuero cosido: oro-negro-rosa-fluo-fucsia
A20: 2032/30 | B20: COLLAR PUAS Y TACHAS STRASS 20mm | C20: =+'[2]C.S.C.20 mm'!$U$10 -> 7100 | E20: =+D20*C20 -> 0
A21: 2032/35 | B21: COLLAR PUAS Y TACHAS STRASS 20mm | C21: =+'[2]C.S.C.20 mm'!$U$10+50 -> 7150 | E21: =+D21*C21 -> 0
A22: 2032/40 | B22: COLLAR PUAS Y TACHAS STRASS 20mm | C22: =+'[2]C.S.C.20 mm'!$U$10+100 -> 7200 | E22: =+D22*C22 -> 0
A23: 2032/45 | B23: COLLAR PUAS Y TACHAS STRASS 20mm | C23: =+'[2]C.S.C.20 mm'!$U$10+150 -> 7250 | E23: =+D23*C23 -> 0
A24: Cod.-Talle | B24: COLLAR NYLON FASHION 20mm | F24: Colores: oro-plata-blanco-francia-celeste-violeta-fucsia-rosa-rojo-negro
A25: 2040/30 | B25: COLLAR NYLON FASHION 20mm | C25: =+'[2]C.PO. 20 mm'!$R$60 -> 5300 | E25: =+D25*C25 -> 0
A26: 2040/35 | B26: COLLAR NYLON FASHION 20mm | C26: =+'[2]C.PO. 20 mm'!$R$61 -> 5350 | E26: =+D26*C26 -> 0
A27: 2040/40 | B27: COLLAR NYLON FASHION 20mm | C27: =+'[2]C.PO. 20 mm'!$R$62 -> 5400 | E27: =+D27*C27 -> 0
A28: 2040/45 | B28: COLLAR NYLON FASHION 20mm | C28: =+'[2]C.PO. 20 mm'!$R$63 -> 5450 | E28: =+D28*C28 -> 0
A29: 2040/50 | B29: COLLAR NYLON FASHION 20mm | C29: =+'[2]C.PO. 20 mm'!$R$64 -> 5500 | E29: =+D29*C29 -> 0
A30: 2040/C0 | B30: CORREA NYLON FASHION 20mm (1,20 m) | C30: =+'[4]C.PO. 20 mm'!$R$4 -> 6200 | E30: =+D30*C30 -> 0
A31: Cod.-Talle | B31: COLLAR TERCIOPELO C/LENTEJUELAS 20mm | F31: Colores: rosa-rojo-violeta
A32: 2051/30 | B32: COLLAR TERCIOPELO C/LENTEJUELAS 20mm | C32: =+'[2]C.PO. 20 mm'!$R$45 -> 5350 | E32: =+D32*C32 -> 0
A33: 2051/35 | B33: COLLAR TERCIOPELO C/LENTEJUELAS 20mm | C33: =+'[2]C.PO. 20 mm'!$R$46 -> 5400 | E33: =+D33*C33 -> 0
A34: 2051/40 | B34: COLLAR TERCIOPELO C/LENTEJUELAS 20mm | C34: =+'[2]C.PO. 20 mm'!$R$47 -> 5450 | E34: =+D34*C34 -> 0
A35: 2051/45 | B35: COLLAR TERCIOPELO C/LENTEJUELAS 20mm | C35: =+'[2]C.PO. 20 mm'!$R$48 -> 5500 | E35: =+D35*C35 -> 0
A36: 2051/50 | B36: COLLAR TERCIOPELO C/LENTEJUELAS 20mm | C36: =+'[2]C.PO. 20 mm'!$R$48+50 -> 5550 | E36: =+D36*C36 -> 0
A37: Cod.-Talle | B37: COLLAR LETRAS STRASS 20mm | F37: Simil cuero cosido: negro-oro-rojo-plata-fluo-fucsia-rosa-francia Charol: negro-rojo-violeta-azul francia-fucsia
A38: 2052/30 | B38: COLLAR CON LETRAS STRASS 20mm | C38: =+'[2]C.S.C.20 mm'!$U$4 -> 11300 | E38: =+D38*C38 -> 0
A39: 2052/35 | B39: COLLAR CON LETRAS STRASS 20mm | C39: =+'[2]C.S.C.20 mm'!$U$4+50 -> 11350 | E39: =+D39*C39 -> 0
A40: 2052/40 | B40: COLLAR CON LETRAS STRASS 20mm | C40: =+'[2]C.S.C.20 mm'!$U$4+100 -> 11400 | E40: =+D40*C40 -> 0
...

Sheet Ancho 25mm
A1: COLLAR ANCHO 25 mm
B2: Productos para PERROS | C2: Precio Unit | D2: Cantidad | E2: Precio Total | F2: Colores de tu preferencia
A3: Cod.-Talle | B3: COLLAR NYLON LISO C/ PASADOR CUERINA Y DIJE 25mm | F3: Colores: rojo-negro-francia-rosa-violeta-fucsia-naranja
A4: 2510/40 | B4: COLLAR NYLON LISO C/ PASADOR CUERINA Y DIJE 25mm | C4: =+'[2]C.25 mm'!$S$27 -> 5100 | E4: =+D4*C4 -> 0
A5: 2510/45 | B5: COLLAR NYLON LISO C/ PASADOR CUERINA Y DIJE 25mm | C5: =+'[2]C.25 mm'!$S$28 -> 5150 | E5: =+D5*C5 -> 0
A6: 2510/50 | B6: COLLAR NYLON LISO C/ PASADOR CUERINA Y DIJE 25mm | C6: =+'[2]C.25 mm'!$S$29 -> 5200 | E6: =+D6*C6 -> 0
A7: 2510/55 | B7: COLLAR NYLON LISO C/ PASADOR CUERINA Y DIJE 25mm | C7: =+'[2]C.25 mm'!$S$30 -> 5250 | E7: =+D7*C7 -> 0
A8: 2510/CO | B8: CORREA NYLON LISO C/MOSQUETON REFORZADO 25mm (1,20 m) | C8: =+'[2]C.25 mm'!$S$3 -> 5150 | E8: =+D8*C8 -> 0
A9: Cod.-Talle | B9: COLLAR NYLON FASHION 25mm | F9: Colores: oro-plata-blanco-francia-celeste-violeta-fucsia-rosa-rojo-negro
A10: 2540/45 | B10: COLLAR NYLON FASHION 25mm | C10: =+'[2]C.25 mm'!$S$55 -> 5950 | E10: =+D10*C10 -> 0
A11: 2540/50 | B11: COLLAR NYLON FASHION 25mm | C11: =+'[2]C.25 mm'!$S$56 -> 6000 | E11: =+D11*C11 -> 0
A12: 2540/55 | B12: COLLAR NYLON FASHION 25mm | C12: =+'[2]C.25 mm'!$S$57 -> 6050 | E12: =+D12*C12 -> 0
A13: 2540/60 | B13: COLLAR NYLON FASHION 25mm | C13: =+'[2]C.25 mm'!$S$58 -> 6100 | E13: =+D13*C13 -> 0
A14: 2540/C0 | B14: CORREA NYLON FASHION 25mm (1,20 m) | C14: =+'[2]C.30 mm'!$V$8 -> 6500 | E14: =+D14*C14 -> 0
A15: Cod.-Talle | B15: COLLAR NYLON MOSTACILLA MULTICOLOR Y DIJE 25mm | F15: Colores: turqueza-naranja-violeta-rojo-fucsia-francia-negro-rosa
A16: 2550/40 | B16: COLLAR NYLON MOSTACILLA MULTICOLOR Y DIJE 25mm | C16: =+'[2]C.25 mm'!$S$33 -> 7750 | E16: =+D16*C16 -> 0
A17: 2550/45 | B17: COLLAR NYLON MOSTACILLA MULTICOLOR Y DIJE 25mm | C17: =+'[2]C.25 mm'!$S$34 -> 7800 | E17: =+D17*C17 -> 0
A18: 2550/50 | B18: COLLAR NYLON MOSTACILLA MULTICOLOR Y DIJE 25mm | C18: =+'[2]C.25 mm'!$S$35 -> 7850 | E18: =+D18*C18 -> 0
A19: 2550/55 | B19: COLLAR NYLON MOSTACILLA MULTICOLOR Y DIJE 25mm | C19: =+'[2]C.25 mm'!$S$36 -> 7900 | E19: =+D19*C19 -> 0
A20: 2550/60 | B20: COLLAR NYLON MOSTACILLA MULTICOLOR Y DIJE 25mm | C20: =+'[2]C.25 mm'!$S$37 -> 7950 | E20: =+D20*C20 -> 0
A21: 2550/65 | B21: COLLAR NYLON MOSTACILLA MULTICOLOR Y DIJE 25mm | C21: =+'[2]C.25 mm'!$S$38 -> 8000 | E21: =+D21*C21 -> 0
A22: 2550/CO | B22: CORREA NYLON MOSTACILLA MULTICOLOR C/MOSQUETON REFORZADO 25mm (1,20 m) | C22: =+'[2]C.25 mm'!$S$8 -> 6300 | E22: =+D22*C22 -> 0
A23: Cod.-Talle | B23: COLLAR NYLON ESTAMPADO C/ PASADOR CUERINA Y DIJE 25mm | F23: Pedir fotos de los espampados en STOCK
A24: 2560/40 | B24: COLLAR ESTAMPADO C/ PASADOR CUERINA Y DIJE 25mm | C24: =+'[2]C.25 mm'!$S$41 -> 5250 | E24: =+D24*C24 -> 0
A25: 2560/45 | B25: COLLAR ESTAMPADO C/ PASADOR CUERINA Y DIJE 25mm | C25: =+'[2]C.25 mm'!$S$42 -> 5300 | E25: =+D25*C25 -> 0
A26: 2560/50 | B26: COLLAR ESTAMPADO C/ PASADOR CUERINA Y DIJE 25mm | C26: =+'[2]C.25 mm'!$S$43 -> 5350 | E26: =+D26*C26 -> 0
A27: 2560/55 | B27: COLLAR ESTAMPADO C/ PASADOR CUERINA Y DIJE 25mm | C27: =+'[2]C.25 mm'!$S$44 -> 5400 | E27: =+D27*C27 -> 0
A28: 2560/60 | B28: COLLAR ESTAMPADO C/ PASADOR CUERINA Y DIJE 25mm | C28: =+'[2]C.25 mm'!$S$44+50 -> 5450 | E28: =+D28*C28 -> 0
A29: 2560/CO | B29: CORREA ESTAMPADO 25mm (1,20 m) | C29: =+'[2]C.25 mm'!$S$7 -> 5450 | E29: =+D29*C29 -> 0
A30: Cod.-Talle | B30: COLLAR AJUSTABLES 25 mm (desde 34cm hasta 60cm) | F30: Colores Fashion: oro-plata-blanco-francia-celeste-violeta-fucsia-rosa-rojo-negro Pedir fotos de los estampados en STOCK
A31: 2572/55 | B31: COLLAR AJUSTABLE FASHION 25mm | C31: =+'[2]Collar ajustable'!$U$52 -> 6400 | E31: =+D31*C31 -> 0
A32: 2573/55 | B32: COLLAR AJUSTABLE ESTAMPADO 25mm | C32: =+'[2]Collar ajustable'!$U$50 -> 5400 | E32: =+D32*C32 -> 0
A33: NOTAS | C33: SUBTOTAL | D33: =SUM(D4:D32) -> 0 | E33: =SUM(E4:E32) -> 0
A35: PRETALES ANCHO 25mm cont. Cuello min.32 cm max. 54 cm cont. Pecho min. 42 cm max. 62 cm
C36: Precio Unit | D36: Cantidad | E36: Precio Total | F36: Colores de tu preferencia
A37: Cod.-Talle | B37: CONJUNTO PRETAL H ESTAMPADO 25mm | F37: Pedir fotos de los estampados en STOCK
A38: 2593/25mm | B38: CONJUNTO PRETAL H ESTAMPADO 25mm $ 15.6000 | C38: =+'[4]Pretal 25 mm'!$S$38+'[4]C.25 mm'!$S$7 -> 21050 | E38: =+D38*C38 -> 0
A39: 2593/C0 | B39: CORREA (1,20 m) | C39: =+'[2]C.25 mm'!$S$7 -> 5450 | E39: Incluye correa
A40: Cod.-Talle | B40: PRETAL H REGULABLE NYLON LISO 25mm | F40: Nylon: negro-rojo-violeta-fucsia
A41: PRONTO | B41: PRETAL H REGULABLE NYLON LISO 25mm | E41: =+D41*C41 -> 0
...

Sheet Ancho 30mm
A1: COLLAR ANCHO 30mm
B2: Productos para PERROS | C2: Precio Unit | D2: Cantidad | E2: Precio Total | F2: Colores de tu preferencia
A3: Cod.-Talle | B3: COLLAR NYLON LISO C/ PASADOR CUERINA Y DIJE 30 mm | F3: Nylon: verde- naranja-rojo-negro-francia-rosa-violeta-fucsia
A4: 3010/40 | B4: COLLAR NYLON LISO C/ PASADOR CUERINA Y DIJE 30mm | C4: =+'[2]C.30 mm'!$V$26 -> 5700 | E4: =+D4*C4 -> 0
A5: 3010/45 | B5: COLLAR NYLON LISO C/ PASADOR CUERINA Y DIJE 30mm | C5: =+'[2]C.30 mm'!$V$26 -> 5700 | E5: =+D5*C5 -> 0
A6: 3010/50 | B6: COLLAR NYLON LISO C/ PASADOR CUERINA Y DIJE 30mm | C6: =+'[2]C.30 mm'!$V$28 -> 5750 | E6: =+D6*C6 -> 0
A7: 3010/55 | B7: COLLAR NYLON LISO C/ PASADOR CUERINA Y DIJE 30mm | C7: =+'[2]C.30 mm'!$V$28 -> 5750 | E7: =+D7*C7 -> 0
A8: 3010/60 | B8: COLLAR NYLON LISO C/ PASADOR CUERINA Y DIJE 30mm | C8: =+'[2]C.30 mm'!$V$30 -> 5800 | E8: =+D8*C8 -> 0
A9: 3010/65 | B9: COLLAR NYLON LISO C/ PASADOR CUERINA Y DIJE 30mm | C9: =+'[2]C.30 mm'!$V$30 -> 5800 | E9: =+D9*C9 -> 0
A10: 3010/C0 | B10: CORREA NYLON LISO C/ MOSQUETON REFORZADO 30mm (1,20 m) | C10: =+'[4]C.30 mm'!$V$3 -> 5760 | E10: =+D10*C10 -> 0
A11: Cod.-Talle | B11: COLLAR NYLON TEXANO 30 mm | F11: Nylon: verde- naranja-rojo-negro-francia-rosa-violeta-fucsia
A12: 3020/40 | B12: COLLAR NYLON TEXANO 30mm | C12: =+'[2]C.30 mm'!$V$60 -> 7400 | E12: =+D12*C12 -> 0
A13: 3020/45 | B13: COLLAR NYLON TEXANO 30mm | C13: =+'[2]C.30 mm'!$V$60 -> 7400 | E13: =+D13*C13 -> 0
A14: 3020/50 | B14: COLLAR NYLON TEXANO 30mm | C14: =+'[2]C.30 mm'!$V$61 -> 7450 | E14: =+D14*C14 -> 0
A15: 3020/55 | B15: COLLAR NYLON TEXANO 30mm | C15: =+'[2]C.30 mm'!$V$61 -> 7450 | E15: =+D15*C15 -> 0
A16: 3020/60 | B16: COLLAR NYLON TEXANO 30mm | C16: =+'[2]C.30 mm'!$V$62 -> 7500 | E16: =+D16*C16 -> 0
A17: 3020/65 | B17: COLLAR NYLON TEXANO 30mm | C17: =+'[2]C.30 mm'!$V$62 -> 7500 | E17: =+D17*C17 -> 0
A18: 3020/C0 | B18: CORREA NYLON LISO C/ MOSQUETON REFORZADO 30mm (1,20 m) | C18: =+'[4]C.30 mm'!$V$3 -> 5760 | E18: =+D18*C18 -> 0
A19: Cod.-Talle | B19: COLLAR NYLON PUAS 30 mm | F19: Nylon: verde- naranja-rojo-negro-francia-rosa-violeta-fucsia
A20: 3030/40 | B20: COLLAR NYLON PUAS 30mm | C20: =+'[2]C.30 mm'!$V$72 -> 7400 | E20: =+D20*C20 -> 0
A21: 3030/45 | B21: COLLAR NYLON PUAS 30mm | C21: =+'[2]C.30 mm'!$V$72 -> 7400 | E21: =+D21*C21 -> 0
A22: 3030/50 | B22: COLLAR NYLON PUAS 30mm | C22: =+'[2]C.30 mm'!$V$73 -> 7450 | E22: =+D22*C22 -> 0
A23: 3030/55 | B23: COLLAR NYLON PUAS 30mm | C23: =+'[2]C.30 mm'!$V$73 -> 7450 | E23: =+D23*C23 -> 0
A24: 3030/60 | B24: COLLAR NYLON PUAS 30mm | C24: =+'[2]C.30 mm'!$V$74 -> 7500 | E24: =+D24*C24 -> 0
A25: 3030/65 | B25: COLLAR NYLON PUAS 30mm | C25: =+'[2]C.30 mm'!$V$74 -> 7500 | E25: =+D25*C25 -> 0
A26: 3030/C0 | B26: CORREA NYLON LISO C/ MOSQUETON REFORZADO 30mm (1,20 m) | C26: =+'[4]C.30 mm'!$V$3 -> 5760 | E26: =+D26*C26 -> 0
A27: Cod.-Talle | B27: COLLAR NYLON TACHAS STRASS 30 mm | F27: Nylon: verde- naranja-rojo-negro-francia-rosa-violeta-fucsia
A28: 3031/40 | B28: COLLAR NYLON TACHAS STRASS 30mm | C28: =+'[2]C.30 mm'!$V$56 -> 6300 | E28: =+D28*C28 -> 0
A29: 3031/45 | B29: COLLAR NYLON TACHAS STRASS 30mm | C29: =+'[2]C.30 mm'!$V$56 -> 6300 | E29: =+D29*C29 -> 0
A30: 3031/50 | B30: COLLAR NYLON TACHAS STRASS 30mm | C30: =+'[2]C.30 mm'!$V$57 -> 6350 | E30: =+D30*C30 -> 0
A31: 3031/55 | B31: COLLAR NYLON TACHAS STRASS 30mm | C31: =+'[2]C.30 mm'!$V$57 -> 6350 | E31: =+D31*C31 -> 0
A32: 3031/60 | B32: COLLAR NYLON TACHAS STRASS 30mm | C32: =+'[2]C.30 mm'!$V$58 -> 6400 | E32: =+D32*C32 -> 0
A33: 3031/65 | B33: COLLAR NYLON TACHAS STRASS 30mm | C33: =+'[2]C.30 mm'!$V$58 -> 6400 | E33: =+D33*C33 -> 0
A34: 3031/C0 | B34: CORREA NYLON LISO C/ MOSQUETON REFORZADO 30mm (1,20 m) | C34: =+'[4]C.30 mm'!$V$3 -> 5760 | E34: =+D34*C34 -> 0
A35: Cod.-Talle | B35: COLLAR NYLON PUAS Y TACHAS STRASS 30 mm | F35: Nylon: verde- naranja-rojo-negro-francia-rosa-violeta-fucsia
A36: 3032/40 | B36: COLLAR NYLON PUAS Y TACHAS STRASS | C36: =+'[2]C.30 mm'!$V$68 -> 6550 | E36: =+D36*C36 -> 0
A37: 3032/45 | B37: COLLAR NYLON PUAS Y TACHAS STRASS | C37: =+'[2]C.30 mm'!$V$68 -> 6550 | E37: =+D37*C37 -> 0
A38: 3032/50 | B38: COLLAR NYLON PUAS Y TACHAS STRASS | C38: =+'[2]C.30 mm'!$V$69 -> 6600 | E38: =+D38*C38 -> 0
A39: 3032/55 | B39: COLLAR NYLON PUAS Y TACHAS STRASS | C39: =+'[2]C.30 mm'!$V$69 -> 6600 | E39: =+D39*C39 -> 0
A40: 3032/60 | B40: COLLAR NYLON PUAS Y TACHAS STRASS | C40: =+'[2]C.30 mm'!$V$70 -> 6650 | E40: =+D40*C40 -> 0
...

Sheet Ancho 40mm
A1: COLLAR ANCHO 40mm
B2: Productos para PERROS GRANDES! Ideal para GALGOS | C2: Precio Unit | D2: Cantidad | E2: Precio Total | F2: Colores de tu preferencia
A3: Cod.-Talle | B3: COLLAR ESTAMPADO ANCHO REFORZADO 40mm o 4cm | F3: Pedir fotos de los estampados en STOCK
A4: 4060/45 | B4: COLLAR ESTAMPADO ANCHO REFORZADO 40mm | C4: =+[2]Martingale!$V$5-200 -> 8100 | E4: =+D4*C4 -> 0
A5: 4060/50 | B5: COLLAR ESTAMPADO ANCHO REFORZADO 40mm | C5: =+[2]Martingale!$V$5-150 -> 8150 | E5: =+D5*C5 -> 0
A6: 4060/55 | B6: COLLAR ESTAMPADO ANCHO REFORZADO 40mm | C6: =+[2]Martingale!$V$5-100 -> 8200 | E6: =+D6*C6 -> 0
A7: 4060/60 | B7: COLLAR ESTAMPADO ANCHO REFORZADO 40mm | C7: =+[2]Martingale!$V$5-50 -> 8250 | E7: =+D7*C7 -> 0
A8: 4060/65 | B8: COLLAR ESTAMPADO ANCHO REFORZADO 40mm | C8: =+[2]Martingale!$V$5 -> 8300 | E8: =+D8*C8 -> 0
A9: 4060/RE | B9: CORREA ESTAMPADA REGULABLE 40mm (Max: 1,20 m Min: 0,70 m) | C9: =+[4]Martingale!$V$49 -> 6900 | E9: =+D9*C9 -> 0
A10: 4060/C0 | B10: CORREA ESTAMPADA SIMPLE 40mm (1,20 m) | C10: =+[4]Martingale!$V$47 -> 6500 | E10: =+D10*C10 -> 0
A11: Cod.-Talle | B11: COLLARES MARTINGALE 4 cm (SEMI AHORQUE Y REGULABLES min.35 - max. 53, ANCHO 4 cm) | F11: Pedir fotos de los estampados en STOCK
A12: 4080/45 | B12: COLLAR MARTINGALE REFORZADO ESTAMPADO ANCHO 40mm ( minimo 35 cm - maximo 53 cm ) | C12: =+[2]Martingale!$V$19 -> 7200 | E12: =+D12*C12 -> 0
A13: 4080/55 | B13: COLLAR MARTINGALE REFORZADO ESTAMPADO ANCHO 40mm ( minimo 41 cm - maximo 64 cm ) | C13: =+[2]Martingale!$V$20 -> 7500 | E13: =+D13*C13 -> 0
A14: 4080/RE | B14: CORREA ESTAMPADA REGULABLE 40mm (Max: 1,20 m Min: 0,70 m) | C14: =+[4]Martingale!$V$49 -> 6900 | E14: =+D14*C14 -> 0
A15: 4080/C0 | B15: CORREA ESTAMPADA SIMPLE 40mm (1,20 m) | C15: =+[4]Martingale!$V$47 -> 6500 | E15: =+D15*C15 -> 0
A16: NOTAS | C16: SUBTOTAL | D16: =SUM(D4:D15) -> 0 | E16: =SUM(E4:E15) -> 0
A18: PRETALES ANCHO 40mm cont. Cuello min.46 cm max. 72 cm cont. Pecho min. 56 cm max. 96 cm
C19: Precio Unit | D19: Cantidad | E19: Precio Total | F19: Colores de tu preferencia
A20: Cod.-Talle | B20: CONJUNTO PRETAL H ESTAMPADO 40mm | F20: Pedir fotos de los estampados en STOCK
A21: 4090/40mm | B21: CONJUNTO PRETAL H ESTAMPADO 40mm $ 19.800 | C21: =+'[4]Pretal 30 mm'!$S$51+[4]Martingale!$V$47 -> 26300 | E21: =+D21*C21 -> 0
A22: 4090/C0 | B22: CORREA (1,20 m) | C22: =+[4]Martingale!$V$47 -> 6500 | E22: Incluye correa
A23: NOTAS | C23: SUBTOTAL | D23: =SUM(D21:D22) -> 0 | E23: =SUM(E21:E22) -> 0

Sheet Ancho 50mm
A1: COLLAR ANCHO 50mm
B2: Productos para PERROS GRANDES! Ideal para GALGOS | C2: Precio Unit | D2: Cantidad | E2: Precio Total | F2: Colores de tu preferencia
A3: Cod.-Talle | B3: COLLAR ESTAMPADO ANCHO REFORZADO 50mm o 5cm | F3: Pedir fotos de los estampados en STOCK
A4: 5060/45 | B4: COLLAR ESTAMPADO ANCHO REFORZADO 50mm | C4: =+[2]Martingale!$V$7-50 -> 8650 | E4: =+D4*C4 -> 0
A5: 5060/50 | B5: COLLAR ESTAMPADO ANCHO REFORZADO 50mm | C5: =+[2]Martingale!$V$7 -> 8700 | E5: =+D5*C5 -> 0
A6: 5060/55 | B6: COLLAR ESTAMPADO ANCHO REFORZADO 50mm | C6: =+[2]Martingale!$V$8 -> 8750 | E6: =+D6*C6 -> 0
A7: 5060/60 | B7: COLLAR ESTAMPADO ANCHO REFORZADO 50mm | C7: =+[2]Martingale!$V$9 -> 8800 | E7: =+D7*C7 -> 0
A8: 5060/65 | B8: COLLAR ESTAMPADO ANCHO REFORZADO 50mm | C8: =+[2]Martingale!$V$10 -> 8850 | E8: =+D8*C8 -> 0
A9: 5060/70 | B9: COLLAR ESTAMPADO ANCHO REFORZADO 50mm | C9: =+[2]Martingale!$V$11 -> 8900 | E9: =+D9*C9 -> 0
A10: 5060/75 | B10: COLLAR ESTAMPADO ANCHO REFORZADO 50mm | C10: =+[2]Martingale!$V$12 -> 8950 | E10: =+D10*C10 -> 0
A11: 5060/RE | B11: CORREA ESTAMPADA REGULABLE 50mm (Max: 1,20 m Min: 0,70 m) | C11: =+[4]Martingale!$V$52 -> 7400 | E11: =+D11*C11 -> 0
A12: 5060/CO | B12: CORREA ESTAMPADA SIMPLE 50mm (1,20 m) | C12: =+[4]Martingale!$V$53 -> 6600 | E12: =+D12*C12 -> 0
A13: Cod.-Talle | B13: COLLAR MARTINGALE 50mm o 5 cm (SEMI AHORQUE Y REGULABLES min.35 - max. 53) | F13: Pedir fotos de los estampados en STOCK
A14: 5080/45 | B14: COLLAR MARTINGALE REFORZADO ESTAMPADO ANCHO 50mm | C14: =+[2]Martingale!$V$35 -> 8150 | E14: =+D14*C14 -> 0
A15: 5080/55 | B15: COLLAR MARTINGALE REFORZADO ESTAMPADO ANCHO 50mm | C15: =+[2]Martingale!$V$36 -> 8450 | E15: =+D15*C15 -> 0
A16: 5080/RE | B16: CORREA ESTAMPADA REGULABLE 50mm (Max: 1,20 m Min: 0,70 m) | C16: =+[4]Martingale!$V$52 -> 7400 | E16: =+D16*C16 -> 0
A17: 5080/CO | B17: CORREA ESTAMPADA SIMPLE 50mm (1,20 m) | C17: =+[4]Martingale!$V$53 -> 6600 | E17: =+D17*C17 -> 0
A18: NOTAS | C18: SUBTOTAL | D18: =SUM(D4:D17) -> 0 | E18: =SUM(E4:E17) -> 0
A20: PRETALES ANCHO 50mm cont. Cuello min.52 cm max. 80 cm cont. Pecho min. 66 cm max. 84 cm
C21: Precio Unit | D21: Cantidad | E21: Precio Total | F21: Colores de tu preferencia
A22: Cod.-Talle | B22: CONJUNTO PRETAL H ESTAMPADO 50mm | F22: Pedir fotos de los estampados en STOCK
A23: 5090/50mm | B23: CONJUNTO PRETAL H ESTAMPADO 50mm $ 22.800 | C23: =+'[4]Pretal 30 mm'!$S$59+[4]Martingale!$V$53 -> 29400 | E23: =+D23*C23 -> 0
A24: 5090/C0 | B24: CORREA (1,20 m) | C24: =+[4]Martingale!$V$53 -> 6600 | E24: Incluye correa
A25: NOTAS | C25: SUBTOTAL | D25: =SUM(D23:D24) -> 0 | E25: =SUM(E23:E24) -> 0
